<?xml version="1.0"?>

<robot name="mobile_robot">

<!--   <link name="base_link">
        <visual>
        <origin rpy="0 0 0" xyz="0 0 0"/>
        <geometry>
            <cylinder length="0.02" radius="0.15"/>
        </geometry>
        <material name="yellow">
        	<color rgba="1 1 1 1"/>
        </material>
        </visual>	 -->
<link name="base_link">
    <visual>
      <origin xyz="0 0 0.05" rpy="0 0 0"/>
      <geometry>
        <mesh filename="package://ai/mesh/AMR/Assembly1.stl" scale="0.001 0.001 0.001"/>
      </geometry>
      <!-- <material name="light_black"/> -->
    </visual>

    <collision>
      <origin xyz="0 0 0.05" rpy="0 0 0"/>
      <geometry>
        <mesh filename="package://ai/mesh/AMR/Assembly1.stl" scale="0.001 0.001 0.001"/>
      </geometry>
    </collision>

    <inertial>
      <origin xyz="0 0 0" rpy="0 0 0"/>
      <mass value="15"/>
      <inertia ixx="0.1" ixy="0" ixz="0"
               iyy="0.1" iyz="0"
               izz="0.1" />
    </inertial>
  </link>
<gazebo reference="base_link">
    <material>Gazebo/DarkGrey</material>
  </gazebo>
  <!-- <link name="base_footprint"/>

  <joint name="base_joint" type="fixed">
    <parent link="base_footprint"/>
    <child link="base_link"/>
    <origin xyz="0.0 0.0 0.0" rpy="0 0 0"/>
  </joint> -->

  <link name="wheel_left_link">
    <visual>
      <origin xyz="0 0 0" rpy="0 0 -1.570"/>
      <geometry>
        <mesh filename="package://ai/mesh/AMR/aa.stl" scale="0.001 0.001 0.001"/>
      </geometry>
      <material name="dark"/>
    </visual>

    <collision>
      <origin xyz="0 0 0" rpy="0 0 -1.570"/>
      <geometry>
        <mesh filename="package://ai/mesh/AMR/aa.stl" scale="0.001 0.001 0.001"/>
      </geometry>
    </collision>

    <inertial>
      <origin xyz="0 0 0" />
      <mass value="5" />
      <inertia ixx="0.1" ixy="0" ixz="0"
               iyy="0.1" iyz="0"
               izz="0.1" />
      </inertial>
  </link>
  <joint name="wheel_left_joint" type="continuous">
    <parent link="base_link"/>
    <child link="wheel_left_link"/>
    <origin xyz="0 -0.155 0.03" rpy="0 0 0"/>
    <axis xyz="0 1 0"/>
  </joint>

    <link name="wheel_right_link">
    <visual>
      <origin xyz="0 0 0" rpy="0 0 1.570"/>
      <geometry>
        <mesh filename="package://ai/mesh/AMR/aa.stl" scale="0.001 0.001 0.001"/>
      </geometry>
      <material name="dark"/>
    </visual>

    <collision>
      <origin xyz="0 0 0" rpy="0 0 1.570"/>
      <geometry>
        <mesh filename="package://ai/mesh/AMR/aa.stl" scale="0.001 0.001 0.001"/>
      </geometry>
    </collision>

    <inertial>
      <origin xyz="0 0 0" />
      <mass value="5" />
      <inertia ixx="0.1" ixy="0" ixz="0"
               iyy="0.1" iyz="0"
               izz="0.1" />
      </inertial>
  </link>
  <joint name="wheel_right_joint" type="continuous">
    <parent link="base_link"/>
    <child link="wheel_right_link"/>
    <origin xyz="0 0.2 0.03" rpy="0 0 0"/>
    <axis xyz="0 1 0"/>
  </joint>

  <link name="caster">
  <visual>
  <origin xyz="0 0 0" rpy="0 0 1.570"/>
      <geometry>
          <mesh filename="package://ai/mesh/AMR/caster.stl" scale="0.0004 0.0004 0.0004"/>
      </geometry>
      <material name="dark"/>
  </visual>
  <collision>
      <origin xyz="0 0 0" rpy="0 0 1.570"/>
      <geometry>
          <mesh filename="package://ai/mesh/AMR/caster.stl" scale="0.0004 0.0004 0.0004"/>
      </geometry>
    </collision>

    <inertial>
      <origin xyz="0 0 0" />
      <mass value="5" />
      <inertia ixx="0.1" ixy="0" ixz="0"
               iyy="0.1" iyz="0"
               izz="0.1" />
      </inertial>

  </link>
  <joint name="wheel_caster_joint" type="fixed">
    <parent link="base_link"/>
    <child link="caster"/>
    <origin xyz="-0.67 0.025 0.03" rpy="0 -1.57 0"/>
    <axis xyz="0 1 0"/>
  </joint>
  <!--box -->
  <link name="box">
    <visual>
      <origin xyz="-0.275 0.02 0.05" rpy="0 0 0"/>
      <geometry>
        <box size="1 0.6 0.001"/>
      </geometry>
    </visual>
  </link>

    <collision>
      <origin xyz="0 0 0.05" rpy="0 0 0"/>
      <geometry>
        <box size="0.06 0.1 0.001"/>
      </geometry>
    </collision>

    <inertial>
      <origin xyz="0 0 0" />
      <mass value="1" />
      <inertia ixx="0.1" ixy="0" ixz="0"
               iyy="0.1" iyz="0"
               izz="0.1" />
      </inertial>
    
  <joint name="base_box" type="fixed">
  <parent link="base_link"/>
  <child link="box"/>
  <origin xyz="0 0.0 0.12" rpy="0 0 0"/>
  <axis xyz="0 1 0"/>
  </joint>
  <!--laser scan -->
  <link name="laser_scan">
	<visual>
		<origin xyz="0 0 0.05" rpy="0 0 0"/>
		<geometry>
			<cylinder length="0.1" radius="0.05"/>
		</geometry>
		<material name = "blue">
			 <color rgba="0.0 0.0 0.8 1.0"/>
		</material>
	</visual>
</link> 
<joint name="laser_base_link" type="fixed">
	<origin xyz="-0.5 0 0" rpy="0 0 0"/>
	<parent link="box"/>
	<child link="laser_scan"/>
</joint>

  <gazebo>
	<plugin name="differential_drive" filename="libgazebo_ros_diff_drive.so">
		<robotNamespace>/</robotNamespace>
		<commandTopic>cmd_vel</commandTopic>
		<odometryTopic>odom</odometryTopic>
		<odometryFrame>odom</odometryFrame>
		<robotBaseFrame>base_link</robotBaseFrame>
		<publishWheelTF>false</publishWheelTF>
		<publishOdomTF>true</publishOdomTF>
		<publishWheelJointState>false</publishWheelJointState>
		<legacyMode>true</legacyMode>

		<wheelSeparation>0.167</wheelSeparation>
		<wheelDiameter>0.06056</wheelDiameter>
		<wheelAcceleration>1.0</wheelAcceleration>
		<wheelTorque>20.0</wheelTorque>
		<updateRate>10.0</updateRate>
		<leftJoint>wheel_left_joint</leftJoint>
		<rightJoint>wheel_right_joint</rightJoint>
	</plugin>
</gazebo>

 



<!-- <link name= "_wheel">
    <visual>
     	<origin rpy= "0 0 0" xyz= "0 0 0" />
     	<geometry>
	 		<mesh filename="package://ai/mesh/AMR/Assembly.stl"/>
		</geometry>
     		<material name= "darkgrey">
				<color rgba="1 1 1 1"/>	
			</material>
    </visual>
</link>  -->
    
 <!--   <link name="left_wheel">
    	<visual>
    	<origin rpy="0 1.57 0" xyz="0 0 0"/>
    	<geometry>
    		<cylinder length="0.02" radius="0.04"/>
    	</geometry>
    	</visual>
    </link>
    
   <link name="right_wheel">
    	<visual>
    	<origin rpy="0 1.57 0" xyz="0 0 0"/>
    	<geometry>
    		<cylinder length="0.02" radius="0.04"/>
    	</geometry>
    	</visual>
    </link> 
    
    <link name="caster" >
    	<visual>
    	<origin rpy="0 1.57 0" xyz="0 0 0"/>
    	<geometry>
    		<sphere radius="0.02" />
    	</geometry>
    	</visual>
    </link>
    
    <joint name="joint1" type="continuous" >
    	<origin xyz="-0.15 0 0.0"/>
    	<parent link="base_link"/>
    	<child link="left_wheel"/>
    	<axes xyz="1 0 0"/>
    	<limit effort="300" velocity="0.5" lower="-3.14" upper="3.14"/>
    </joint>  
    
    <joint name="joint2" type="continuous" >
    	<origin xyz="0.15 0 0" />
    	<parent link="base_link" />
    	<child link="right_wheel"/>
    	<axes xyz="1 0 0"/>
    	<limit effort="300" velocity="0.5" lower="-3.14" upper="3.14"/>
    </joint>
      
     <joint name="joint3" type="continuous" >
    	<origin xyz="0.0 0.12 -0.02" />
    	<parent link="base_link" />
    	<child link="caster"/>
    	<axes xyz="0 0 0"/>
    	<limit effort="300" velocity="0.5" lower="-3.14" upper="3.14"/>
    </joint> -->
    
</robot>

















